Workbook

Sheet 振込明細
A1: 銀行振込 支払い表 | D1: 送金日 | E1: 46058 | H1: 四国銀行 | I1: 青即引き・緑伝票引き | K1: 今回手形 | N1: 即引き％引き | O1: %次月伝票
A2: 仕入コード | B2: 送り先 | C2: 請求額 | D2: 打込金額 | E2: 振込金額 | F2: 送料相手 | G2: 自社 | H2: 値引 | I2: 早払い | J2: 相殺 | K2: 大竹 | L2: 広島 | M2: 木原屋 | N2: サラダ館 | O2: 竹の子の里 | P2: 本社
A3: 61 | B3: ＡＲＣ | D3: =C3-H3-I3-J3 -> 0 | E3: =IF(C3="","",D3-F3) | F3: =IF(D3="","",IF(D3=0,"",IF(D3<30000,605,IF(D3>=30000,770)))) | G3: 0 | H3: 0
A4: 81 | B4: 大高製紙 | C4: 18810 | D4: =C4-H4-I4-J4 -> 18246 | E4: =IF(C4="","",D4-F4) -> 17641 | F4: =IF(D4="","",IF(D4=0,"",IF(D4<30000,605,IF(D4>=30000,770)))) -> 605 | G4: 0 | H4: 0 | I4: =S4 -> 564 | S4: =INT(C4*0.03) -> 564 | U4: 3
A5: 85 | B5: 王子製袋 | D5: =C5-H5-I5-J5 -> 0 | E5: =IF(C5="","",D5-F5) | F5: =IF(D5="","",IF(D5=0,"",IF(D5<30000,605,IF(D5>=30000,770)))) | R5: 歩引き終了
A6: 101 | B6: カミ商事 | D6: =C6-H6-I6-J6 -> 0 | E6: =IF(C6="","",D6-F6) | F6: =IF(D6="","",IF(D6=0,"",IF(D6<30000,605,IF(D6>=30000,770)))) | G6: 0 | H6: 0
A7: 103 | B7: 河野製紙 | D7: =C7-H7-I7-J7 -> 0 | E7: =IF(C7="","",D7-F7) | F7: =IF(D7="","",IF(D7=0,"",IF(D7<30000,605,IF(D7>=30000,770)))) | G7: 0 | H7: 0 | U7: 2 | V7: 10万以上
A8: 111 | B8: 花王 業務品 KPS | C8: 808791 | D8: =C8-H8-I8-J8 -> 808791 | E8: =IF(C8="","",D8-F8) -> 808021 | F8: =IF(D8="","",IF(D8=0,"",IF(D8<30000,605,IF(D8>=30000,770)))) -> 770 | G8: 0 | H8: 0 | U8: 3
A9: 112 | B9: 花王 業務品 KPS施設 | D9: =C9-H9-I9-J9 -> 0 | E9: =IF(C9="","",D9-F9) | F9: =IF(D9="","",IF(D9=0,"",IF(D9<30000,605,IF(D9>=30000,770))))
A10: 123 | B10: 金星製紙 | D10: =C10-H10-I10-J10 -> 0 | E10: =IF(C10="","",D10-F10) | F10: =IF(D10="","",IF(D10=0,"",IF(D10<30000,330,IF(D10>=30000,550)))) | G10: 0 | H10: 0
A11: 125 | B11: キンセイ | D11: =C11-H11-I11-J11 -> 0 | E11: =IF(C11="","",D11-F11) | F11: =IF(D11="","",IF(D11=0,"",IF(D11<30000,660,IF(D11>=30000,880))))
A12: 141 | B12: 日本製紙クレシア | C12: 765781 | D12: =C12-H12-I12-J12 -> 765781 | E12: =IF(C12="","",D12-F12) -> 765011 | F12: =IF(D12="","",IF(D12=0,"",IF(D12<30000,605,IF(D12>=30000,770)))) -> 770
A13: 181 | B13: コトブキ製紙 | C13: 53680 | D13: =C13-H13-I13-J13 -> 53680 | E13: =IF(C13="","",D13-F13) -> 52910 | F13: =IF(D13="","",IF(D13=0,"",IF(D13<30000,605,IF(D13>=30000,770)))) -> 770
A14: 187 | B14: ゴークラ | D14: =C14-H14-I14-J14 -> 0 | E14: =IF(C14="","",D14-F14) | F14: =IF(D14="","",IF(D14=0,"",IF(D14<30000,605,IF(D14>=30000,770)))) | R14: 伊予銀行三島支店 当座 2000581
A15: 205 | B15: 三昭紙業 | D15: =C15-H15-I15-J15 -> 0 | E15: =IF(C15="","",D15-F15) | F15: =IF(D15="","",IF(D15=0,"",IF(D15<30000,605,IF(D15>=30000,770)))) | G15: 0 | H15: 0
A16: 207 | B16: 三興化学工業 | D16: =C16-H16-I16-J16 -> 0 | E16: =IF(C16="","",D16-F16) | F16: =IF(D16="","",IF(D16=0,"",IF(D16<30000,110,IF(D16>=30000,330)))) | G16: 0 | H16: 0 | S16: 3万以下振込料負担
A17: 211 | B17: 三友商事 | D17: =C17-H17-I17-J17 -> 0 | E17: =IF(C17="","",D17-F17) | F17: =IF(D17="","",IF(D17=0,"",IF(D17<30000,605,IF(D17>=30000,770)))) | U17: 1.5
A18: 222 | B18: シモジマ | C18: 295581 | D18: =C18-H18-I18-J18 -> 295581 | E18: =IF(C18="","",D18-F18) -> 294811 | F18: =IF(D18="","",IF(D18=0,"",IF(D18<30000,605,IF(D18>=30000,770)))) -> 770 | G18: 0 | H18: 0 | R18: 歩引き終了 | S18: =INT(C18*0.015) -> 4433 | U18: 1.5
A19: 224 | B19: シルバー化成 | D19: =C19-H19-I19-J19 -> 0 | E19: =IF(C19="","",D19-F19) | F19: =IF(D19="","",IF(D19=0,"",IF(D19<30000,605,IF(D19>=30000,770)))) | G19: 0 | H19: 0
A20: 231 | B20: シャディ | C20: 67560 | D20: =C20-H20-I20-J20 -> 67560 | E20: =IF(C20="","",D20-F20) -> 66790 | F20: =IF(D20="","",IF(D20=0,"",IF(D20<30000,605,IF(D20>=30000,770)))) -> 770
A21: 311 | B21: 田宮事務機 | D21: =C21-H21-I21-J21 -> 0 | E21: =IF(C21="","",D21-F21) | F21: =IF(D21="","",IF(D21=0,"",IF(D21<30000,110,IF(D21>=30000,330)))) | G21: 0 | H21: 0
A22: 317 | B22: 立石春洋堂 | D22: =C22-H22-I22-J22 -> 0 | E22: =IF(C22="","",D22-F22) | F22: =IF(D22="","",IF(D22=0,"",IF(D22<30000,660,IF(D22>=30000,880)))) | G22: 0 | H22: 0
A23: 321 | B23: 中日綿業 | D23: =C23-H23-I23-J23 -> 0 | E23: =IF(C23="","",D23-F23) | F23: =IF(D23="","",IF(D23=0,"",IF(D23<30000,605,IF(D23>=30000,770)))) | G23: 0 | H23: 0
A24: 371 | B24: ツバメ工業 | D24: =C24-H24-I24-J24 -> 0 | E24: =IF(C24="","",D24-F24) | F24: =IF(D24="","",IF(D24=0,"",IF(D24<30000,605,IF(D24>=30000,770)))) | G24: 0 | H24: 0
A25: 345 | B25: ツボイ | D25: =C25-H25-I25-J25 -> 0 | E25: =IF(C25="","",D25-F25) | F25: =IF(D25="","",IF(D25=0,"",IF(D25<30000,605,IF(D25>=30000,770)))) | U25: 1.5
A26: 383 | B26: トーヨ | C26: 326029 | D26: =C26-H26-I26-J26 -> 319509 | E26: =IF(C26="","",D26-F26) -> 318739 | F26: =IF(D26="","",IF(D26=0,"",IF(D26<30000,605,IF(D26>=30000,770)))) -> 770 | I26: =S26 -> 6520 | S26: =INT(C26*0.02) -> 6520
A27: 392 | B27: 東芝エルイーソリューション㈱ | D27: =C27-H27-I27-J27 -> 0 | E27: =IF(C27="","",D27-F27) | F27: =IF(D27="","",IF(D27=0,"",IF(D27<30000,605,IF(D27>=30000,770))))
A28: 411 | B28: ㈱ 奈良半商店 | D28: =C28-H28-I28-J28 -> 0 | E28: =IF(C28="","",D28-F28) | F28: =IF(D28="","",IF(D28=0,"",IF(D28<30000,605,IF(D28>=30000,770))))
A29: 421 | B29: 西日本衛材 | C29: 61600 | D29: =C29-H29-I29-J29 -> 60676 | E29: =IF(C29="","",D29-F29) -> 59906 | F29: =IF(D29="","",IF(D29=0,"",IF(D29<30000,605,IF(D29>=30000,770)))) -> 770 | I29: =S29 -> 924 | S29: =INT(C29*0.015) -> 924 | U29: 1.5
A30: 441 | B30: ぬまご | D30: =C30-H30-I30-J30 -> 0 | E30: =IF(C30="","",D30-F30) | F30: =IF(D30="","",IF(D30=0,"",IF(D30<30000,605,IF(D30>=30000,770)))) | G30: 0 | H30: 0
A31: 461 | B31: 王子ネピア 広島 | C31: 875062 | D31: =C31-H31-I31-J31 -> 875062 | E31: =IF(C31="","",D31-F31) -> 874292 | F31: =IF(D31="","",IF(D31=0,"",IF(D31<30000,605,IF(D31>=30000,770)))) -> 770 | G31: 0
A32: 462 | B32: 王子ネピア 直需 | C32: 510510 | D32: =C32-H32-I32-J32 -> 510510 | E32: =IF(C32="","",D32-F32) -> 509740 | F32: =IF(D32="","",IF(D32=0,"",IF(D32<30000,605,IF(D32>=30000,770)))) -> 770 | U32: 2 | V32: 10万以上 | Y32: 315
A33: 501 | B33: ハヤシ商事 | D33: =C33-H33-I33-J33 -> 0 | E33: =IF(C33="","",D33-F33) | F33: =IF(D33="","",IF(D33=0,"",IF(D33<30000,330,IF(D33>=30000,550)))) | G33: 0 | H33: 0
A34: 521 | B34: ヒノマル | D34: =C34-H34-I34-J34 -> 0 | E34: =IF(C34="","",D34-F34) | F34: =IF(D34="","",IF(D34=0,"",IF(D34<30000,660,IF(D34>=30000,880)))) | V34: 2
A35: 544 | B35: フクヤ | C35: 83068 | D35: =C35-H35-I35-J35 -> 83068 | E35: =IF(C35="","",D35-F35) -> 82298 | F35: =IF(D35="","",IF(D35=0,"",IF(D35<30000,605,IF(D35>=30000,770)))) -> 770 | O35: ＣＰ入力
A36: 547 | B36: フレンド | D36: =C36-H36-I36-J36 -> 0 | E36: =IF(C36="","",D36-F36) | F36: =IF(D36="","",IF(D36=0,"",IF(D36<30000,605,IF(D36>=30000,770))))
A37: 601 | B37: 前谷紙工業 | D37: =C37-H37-I37-J37 -> 0 | E37: =IF(C37="","",D37-F37) | F37: =IF(D37="","",IF(D37=0,"",IF(D37<30000,605,IF(D37>=30000,770)))) | G37: 0 | H37: 0
A38: 605 | B38: 松田製袋 | C38: 111100 | D38: =C38-H38-I38-J38 -> 111100 | E38: =IF(C38="","",D38-F38) -> 110550 | F38: =IF(D38="","",IF(D38=0,"",IF(D38<30000,330,IF(D38>=30000,550)))) -> 550 | U38: 1.8
A39: 631 | B39: 三木商事 | C39: 296164 | D39: =C39-H39-I39-J39 -> 296164 | E39: =IF(C39="","",D39-F39) -> 296164 | H39: 0
A40: 701 | B40: 八幡浜紙業 | D40: =C40-H40-I40-J40 -> 0 | E40: =IF(C40="","",D40-F40) | F40: =IF(D40="","",IF(D40=0,"",IF(D40<30000,330,IF(D40>=30000,550)))) | I40: =S40 -> 0 | S40: =INT(C40*0.02) -> 0 | U40: 2
...

Sheet MF変換
A1: 取引No | B1: 取引日 | C1: 借方勘定科目 | D1: 借方補助科目 | E1: 借方部門 | F1: 借方取引先 | G1: 借方税区分 | H1: 借方インボイス | I1: 借方金額(円) | J1: 貸方勘定科目 | K1: 貸方補助科目 | L1: 貸方部門 | M1: 貸方取引先 | N1: 貸方税区分 | O1: 貸方インボイス | P1: 貸方金額(円) | Q1: 摘要 | R1: タグ | S1: メモ
B2: =振込明細!$E$1 -> 46058 | C2: 買掛金 | D2: =IF(IFERROR(VLOOKUP(振込明細!B3,変換MAP!A:B,2,FALSE),"")=0,"",IFERROR(VLOOKUP(振込明細!B3,変換MAP!A:B,2,FALSE),"")) -> ＡＲＣ（株） | G2: 対象外 | I2: =振込明細!C3 -> 0 | J2: 資金複合 | N2: 対象外 | P2: =I2 -> 0 | Q2: =D2 -> ＡＲＣ（株）
B3: =振込明細!$E$1 -> 46058 | C3: 買掛金 | D3: =IF(IFERROR(VLOOKUP(振込明細!B4,変換MAP!A:B,2,FALSE),"")=0,"",IFERROR(VLOOKUP(振込明細!B4,変換MAP!A:B,2,FALSE),"")) -> 大高製紙（株） | G3: 対象外 | I3: =振込明細!C4 -> 18810 | J3: 資金複合 | N3: 対象外 | P3: =I3 -> 18810 | Q3: =D3 -> 大高製紙（株）
B4: =振込明細!$E$1 -> 46058 | C4: 買掛金 | D4: =IF(IFERROR(VLOOKUP(振込明細!B5,変換MAP!A:B,2,FALSE),"")=0,"",IFERROR(VLOOKUP(振込明細!B5,変換MAP!A:B,2,FALSE),"")) -> 王子製袋（株） | G4: 対象外 | I4: =振込明細!C5 -> 0 | J4: 資金複合 | N4: 対象外 | P4: =I4 -> 0 | Q4: =D4 -> 王子製袋（株）
B5: =振込明細!$E$1 -> 46058 | C5: 買掛金 | D5: =IF(IFERROR(VLOOKUP(振込明細!B6,変換MAP!A:B,2,FALSE),"")=0,"",IFERROR(VLOOKUP(振込明細!B6,変換MAP!A:B,2,FALSE),"")) -> カミ商事（株） | G5: 対象外 | I5: =振込明細!C6 -> 0 | J5: 資金複合 | N5: 対象外 | P5: =I5 -> 0 | Q5: =D5 -> カミ商事（株）
B6: =振込明細!$E$1 -> 46058 | C6: 買掛金 | D6: =IF(IFERROR(VLOOKUP(振込明細!B7,変換MAP!A:B,2,FALSE),"")=0,"",IFERROR(VLOOKUP(振込明細!B7,変換MAP!A:B,2,FALSE),"")) -> 河野製紙（株） | G6: 対象外 | I6: =振込明細!C7 -> 0 | J6: 資金複合 | N6: 対象外 | P6: =I6 -> 0 | Q6: =D6 -> 河野製紙（株）
B7: =振込明細!$E$1 -> 46058 | C7: 買掛金 | D7: =IF(IFERROR(VLOOKUP(振込明細!B8,変換MAP!A:B,2,FALSE),"")=0,"",IFERROR(VLOOKUP(振込明細!B8,変換MAP!A:B,2,FALSE),"")) -> 花王プロフェショナルｻｰﾋﾞｽ | G7: 対象外 | I7: =振込明細!C8 -> 808791 | J7: 資金複合 | N7: 対象外 | P7: =I7 -> 808791 | Q7: =D7 -> 花王プロフェショナルｻｰﾋﾞｽ
B8: =振込明細!$E$1 -> 46058 | C8: 買掛金 | D8: =IF(IFERROR(VLOOKUP(振込明細!B9,変換MAP!A:B,2,FALSE),"")=0,"",IFERROR(VLOOKUP(振込明細!B9,変換MAP!A:B,2,FALSE),"")) | G8: 対象外 | I8: =振込明細!C9 -> 0 | J8: 資金複合 | N8: 対象外 | P8: =I8 -> 0 | Q8: =D8
B9: =振込明細!$E$1 -> 46058 | C9: 買掛金 | D9: =IF(IFERROR(VLOOKUP(振込明細!B10,変換MAP!A:B,2,FALSE),"")=0,"",IFERROR(VLOOKUP(振込明細!B10,変換MAP!A:B,2,FALSE),"")) -> 金星製紙（株） | G9: 対象外 | I9: =振込明細!C10 -> 0 | J9: 資金複合 | N9: 対象外 | P9: =I9 -> 0 | Q9: =D9 -> 金星製紙（株）
B10: =振込明細!$E$1 -> 46058 | C10: 買掛金 | D10: =IF(IFERROR(VLOOKUP(振込明細!B11,変換MAP!A:B,2,FALSE),"")=0,"",IFERROR(VLOOKUP(振込明細!B11,変換MAP!A:B,2,FALSE),"")) -> （株）キンセイ | G10: 対象外 | I10: =振込明細!C11 -> 0 | J10: 資金複合 | N10: 対象外 | P10: =I10 -> 0 | Q10: =D10 -> （株）キンセイ
B11: =振込明細!$E$1 -> 46058 | C11: 買掛金 | D11: =IF(IFERROR(VLOOKUP(振込明細!B12,変換MAP!A:B,2,FALSE),"")=0,"",IFERROR(VLOOKUP(振込明細!B12,変換MAP!A:B,2,FALSE),"")) -> 日本製紙クレシア（株） | G11: 対象外 | I11: =振込明細!C12 -> 765781 | J11: 資金複合 | N11: 対象外 | P11: =I11 -> 765781 | Q11: =D11 -> 日本製紙クレシア（株）
B12: =振込明細!$E$1 -> 46058 | C12: 買掛金 | D12: =IF(IFERROR(VLOOKUP(振込明細!B13,変換MAP!A:B,2,FALSE),"")=0,"",IFERROR(VLOOKUP(振込明細!B13,変換MAP!A:B,2,FALSE),"")) -> コトブキ製紙（株） | G12: 対象外 | I12: =振込明細!C13 -> 53680 | J12: 資金複合 | N12: 対象外 | P12: =I12 -> 53680 | Q12: =D12 -> コトブキ製紙（株）
B13: =振込明細!$E$1 -> 46058 | C13: 買掛金 | D13: =IF(IFERROR(VLOOKUP(振込明細!B14,変換MAP!A:B,2,FALSE),"")=0,"",IFERROR(VLOOKUP(振込明細!B14,変換MAP!A:B,2,FALSE),"")) -> ゴークラ | G13: 対象外 | I13: =振込明細!C14 -> 0 | J13: 資金複合 | N13: 対象外 | P13: =I13 -> 0 | Q13: =D13 -> ゴークラ
... B41: =振込明細!$E$1 -> 46058 | C41: 買掛金 | D41: =IF(IFERROR(VLOOKUP(振込明細!B42,変換MAP!A:B,2,FALSE),"")=0,"",IFERROR(VLOOKUP(振込明細!B42,変換MAP!A:B,2,FALSE),"")) -> 柳井紙工（株） | G41: 対象外 | I41: =振込明細!C42 -> 0 | J41: 資金複合 | N41: 対象外 | P41: =I41 -> 0 | Q41: =D41 -> 柳井紙工（株）
B42: =振込明細!$E$1 -> 46058 | C42: 資金複合 | D42: =IF(IFERROR(VLOOKUP(振込明細!B88,変換MAP!A:B,2,FALSE),"")=0,"",IFERROR(VLOOKUP(振込明細!B88,変換MAP!A:B,2,FALSE),"")) | G42: 対象外 | I42: =振込明細!F43 -> 8855 | J42: 仕入値引・戻し高 | L42: 物販事業部 | N42: 課税仕入-返還等 10% | P42: =I42 -> 8855 | Q42: 振込手数料値引／5日払い分
B43: =振込明細!$E$1 -> 46058 | C43: 資金複合 | D43: =IF(IFERROR(VLOOKUP(振込明細!B89,変換MAP!A:B,2,FALSE),"")=0,"",IFERROR(VLOOKUP(振込明細!B89,変換MAP!A:B,2,FALSE),"")) | G43: 対象外 | I43: =振込明細!I43 -> 8008 | J43: 早払収益 | L43: 物販事業部 | N43: 非課税売上 | P43: =I43 -> 8008 | Q43: 早払収益／5日払い分

Sheet 変換MAP
A1: EXCEL | B1: MF
A2: ＡＲＣ | B2: ＡＲＣ（株）
A3: 大高製紙 | B3: 大高製紙（株）
A4: 王子製袋 | B4: 王子製袋（株）
A5: カミ商事 | B5: カミ商事（株）
A6: 河野製紙 | B6: 河野製紙（株）
A7: 花王 業務品 KPS | B7: 花王プロフェショナルｻｰﾋﾞｽ
A8: 花王 業務品 KPS施設
A9: 金星製紙 | B9: 金星製紙（株）
A10: キンセイ | B10: （株）キンセイ
A11: 日本製紙クレシア | B11: 日本製紙クレシア（株）
A12: コトブキ製紙 | B12: コトブキ製紙（株）
A13: ゴークラ | B13: ゴークラ
A14: 三昭紙業 | B14: 三昭紙業（株）
A15: 三興化学工業 | B15: 三興化学工業（株）
A16: 三友商事 | B16: 三友商事（株）
A17: シモジマ | B17: （株）シモジマ
A18: シルバー化成 | B18: （有）シルバー化成工業所
A19: シャディ | B19: シャディ（株）
A20: 田宮事務機 | B20: （株）田宮事務器
... A23: ツバメ工業 | B23: ツバメ工業（株）
A24: ツボイ
A25: トーヨ | B25: （株）トーヨ
A26: 東芝エルイーソリューション㈱
A27: ㈱ 奈良半商店
A28: 西日本衛材 | B28: 西日本衛材（株）
A29: ぬまご | B29: （株）ぬまご
A30: 王子ネピア 広島 | B30: 王子ネピア（株）
A31: 王子ネピア 直需 | B31: 王子ネピア（直需）
A32: ハヤシ商事 | B32: ハヤシ商事（株）
A33: ヒノマル | B33: ヒノマル（株）
A34: フクヤ | B34: （株）フクヤ
A35: フレンド | B35: （株）フレンド
A36: 前谷紙工業 | B36: 前谷紙工業（株）
A37: 松田製袋 | B37: （株）松田製袋
A38: 三木商事 | B38: 三木商事（株）
A39: 八幡浜紙業 | B39: 八幡浜紙業（株）
... A42: シーバイエス ㈱ | B42: シーバイエス（株）
